[TOC]

## 一、错误处理

### 1.1 错误捕获

Python中内置有`try...except...finally...`的错误处理机制。

```python
try:
    print('try...')
    r = 10 / 0
    print('result:', r)
except ZeroDivisionError as e:
    print('except:', e)
finally:
    print('finally...')
print('END')
```

执行，结果如下：
```
try...
except: division by zero
finally...
END
```

当我们认为某些代码可能会出错时，就可以用`try`来运行这段代码，如果执行出错，则后续代码不会继续执行，而是直接跳转至错误处理代码，即`except`语句块，执行完`except`后，如果有`finally`语句块，则执行`finally`语句块，至此，执行完毕。

因错误种类不唯一，通过多个不同的`except`语句块可以捕获不同类型的错误。若无错误，可在`except`语句块后面加一个`else`，此时会自动执行`else`语句。

```python
try:
    print('try...')
    r = 10 / int('2')
    print('result:', r)
except ValueError as e:
    print('ValueError:', e)
except ZeroDivisionError as e:
    print('ZeroDivisionError:', e)
else:
    print('no error!')
finally:
    print('finally...')
print('END')
```

Python所有的错误都是从`BaseException`类派生的，在使用`except`捕获时，会将子类一同捕获。

[常见错误类型](https://docs.python.org/3/library/exceptions.html#exception-hierarchy)

使用`try...except`捕获错误可以跨越多层调用，比如函数`main()`调用`foo()`，`foo()`调用`bar()`，结果`bar()`出错了，这时，只要`main()`捕获到了，就可以处理。

```python
def foo(s):
    return 10 / int(s)

def bar(s):
    return foo(s) * 2

def main():
    try:
        bar('0')
    except Exception as e:
        print('Error:', e)
    finally:
        print('finally...')
```



### 1.2 调用栈

如果错误没有被捕获，它就会一直往上抛，最后被Python解释器捕获，打印一个错误信息，然后程序退出。来看看`err.py`：

```python
# err.py:
def foo(s):
    return 10 / int(s)

def bar(s):
    return foo(s) * 2

def main():
    bar('0')

main()
```

执行，结果如下：

```
$ python3 err.py
Traceback (most recent call last):
  File "err.py", line 11, in <module>
    main()
  File "err.py", line 9, in main
    bar('0')
  File "err.py", line 6, in bar
    return foo(s) * 2
  File "err.py", line 3, in foo
    return 10 / int(s)
ZeroDivisionError: division by zero
```

错误信息第1行：

```
Traceback (most recent call last):
```

告诉我们这是错误的跟踪信息。

第2~3行：

```
  File "err.py", line 11, in <module>
    main()
```

调用`main()`出错了，在代码文件`err.py`的第11行代码，但原因是第9行：

```
  File "err.py", line 9, in main
    bar('0')
```

调用`bar('0')`出错了，在代码文件`err.py`的第9行代码，但原因是第6行：

```
  File "err.py", line 6, in bar
    return foo(s) * 2
```

原因是`return foo(s) * 2`这个语句出错了，但这还不是最终原因，继续往下看：

```
  File "err.py", line 3, in foo
    return 10 / int(s)
```

原因是`return 10 / int(s)`这个语句出错了，这是错误产生的源头，因为下面打印了：

```
ZeroDivisionError: integer division or modulo by zero
```

根据错误类型`ZeroDivisionError`，我们判断，`int(s)`本身并没有出错，但是`int(s)`返回`0`，在计算`10 / 0`时出错，至此，找到错误源头。



### 1.3 错误记录

Python内置的`logging`模块可以非常容易地记录错误信息

```python
# err_logging.py

import logging

def foo(s):
    return 10 / int(s)

def bar(s):
    return foo(s) * 2

def main():
    try:
        bar('0')
    except Exception as e:
        logging.exception(e)

main()
print('END')
```

程序在出错后会打印完错误信息，然后继续执行，并正常退出：

```
$ python3 err_logging.py
ERROR:root:division by zero
Traceback (most recent call last):
  File "err_logging.py", line 13, in main
    bar('0')
  File "err_logging.py", line 9, in bar
    return foo(s) * 2
  File "err_logging.py", line 6, in foo
    return 10 / int(s)
ZeroDivisionError: division by zero
END
```



### 1.4 抛出错误

因为错误是class，捕获一个错误就是捕获到该class的一个实例。因此，错误并不是凭空产生的，而是有意创建并抛出的。Python的内置函数会抛出很多类型的错误，我们自己编写的函数也可以抛出错误。

如果要抛出错误，首先根据需要，可以定义一个错误的class，选择好继承关系，然后，用`raise`语句抛出一个错误的实例：

```python
# err_raise.py
class FooError(ValueError):
    pass

def foo(s):
    n = int(s)
    if n==0:
        raise FooError('invalid value: %s' % s)
    return 10 / n

foo('0')
```

执行结果：

```
$ python3 err_raise.py 
Traceback (most recent call last):
  File "err_throw.py", line 11, in <module>
    foo('0')
  File "err_throw.py", line 8, in foo
    raise FooError('invalid value: %s' % s)
__main__.FooError: invalid value: 0
```

通常情况下，应尽量选择Python已有的内置的错误类型（比如`ValueError`，`TypeError`），尽量使用Python内置的错误类型。

```python
# err_reraise.py

def foo(s):
    n = int(s)
    if n==0:
        raise ValueError('invalid value: %s' % s)
    return 10 / n

def bar():
    try:
        foo('0')
    except ValueError as e:
        print('ValueError!')
        raise

bar()
```

上面的程序，在`bar()`函数中，在捕获了`ValueError!`后，又把错误通过`raise`语句抛出去了，这是一种常见的错误处理方式。捕获错误目的只是记录一下，便于后续追踪，但是，由于当前函数不知道应该怎么处理该错误，所以，最恰当的方式是继续往上抛，让顶层调用者去处理。

`raise`语句如果不带参数，就会把当前错误原样抛出。此外，在`except`中`raise`一个Error，还可以把一种类型的错误转化成另一种类型：

```python
try:
    10 / 0
except ZeroDivisionError:
    raise ValueError('input error!')
```



## 二、调试

### 2.1 断言`assert`

```python
def foo(s):
    n = int(s)
    assert n != 0, 'n is zero!'
    return 10 / n

def main():
    foo('0')
```

`assert`的意思是，表达式`n != 0`应该是`True`，否则，根据程序运行的逻辑，后面的代码肯定会出错。

如果断言失败，`assert`语句本身就会抛出`AssertionError`：

```
$ python err.py
Traceback (most recent call last):
  ...
AssertionError: n is zero!
```

若想关闭`assert`，启动时加上`-0`参数即可。



### 2.2 日志`logging`

`logging`不会抛出错误，可以将错误输出到文件和终端。

```python
import logging
# 修改输出的等级为INFO，info消息输出到终端
logging.basicConfig(level=logging.INFO)

s = '0'
n = int(s)
logging.info('n = %d' % n)
print(10 / n)
```

`logging`允许指定记录信息的级别，有`debug`，`info`，`warning`，`error`等几个级别，当我们指定`level=INFO`时，`logging.debug`就不起作用了。同理，指定`level=WARNING`后，`debug`和`info`就不起作用了。



### 2.3 调试器`pdb`

调试器`pdb`可以让程序单步运行以查看运行状态。

- 启动调试，运行添加参数`-m pdb`

```python
python -m pdb file.py
```

- 运行后，输入命令`l`查看代码
- 运行后，输入命令`n`单步执行
- 运行后，输入命令`p 变量名`，查看变量
- 运行后，输入命令`q`结束调试

通过`pdb.set_trace()`，可以在程序中设置断点：

```python
# err.py
import pdb

s = '0'
n = int(s)
pdb.set_trace() # 运行到这里会自动暂停
print(10 / n)
```

运行代码，程序会自动在`pdb.set_trace()`暂停并进入`pdb`调试环境，可以用命令`p`查看变量，或者用命令`c`继续运行。



## 三、单元测试

### 3.1 简述

单元测试是用来对一个模块、一个函数或者一个类来进行正确性检验的测试工作。

比如对函数`abs()`，我们可以编写出以下几个测试用例：

1. 输入正数，比如`1`、`1.2`、`0.99`，期待返回值与输入相同；
2. 输入负数，比如`-1`、`-1.2`、`-0.99`，期待返回值与输入相反；
3. 输入`0`，期待返回`0`；
4. 输入非数值类型，比如`None`、`[]`、`{}`，期待抛出`TypeError`。

把上面的测试用例放到一个测试模块里，就是一个完整的单元测试。



### 3.2 例子

- **构建单元测试**

我们来编写一个`Dict`类，这个类的行为和`dict`(字典`Dictionary`)一致，但是可以通过属性来访问，用起来就像下面这样：

```
>>> d = Dict(a=1, b=2)
>>> d['a']
1
>>> d.a
1
```

`mydict.py`代码如下：

```python
class Dict(dict):

    def __init__(self, **kw):
        super().__init__(**kw)

    def __getattr__(self, key):
        try:
            return self[key]
        except KeyError:
            raise AttributeError(r"'Dict' object has no attribute '%s'" % key)

    def __setattr__(self, key, value):
        self[key] = value
```

为了编写单元测试，我们需要引入Python自带的`unittest`模块，编写`mydict_test.py`如下：

```python
import unittest

from mydict import Dict

class TestDict(unittest.TestCase):

    def test_init(self):
        d = Dict(a=1, b='test')
        self.assertEqual(d.a, 1)
        self.assertEqual(d.b, 'test')
        self.assertTrue(isinstance(d, dict))

    def test_key(self):
        d = Dict()
        d['key'] = 'value'
        self.assertEqual(d.key, 'value')

    def test_attr(self):
        d = Dict()
        d.key = 'value'
        self.assertTrue('key' in d)
        self.assertEqual(d['key'], 'value')

    def test_keyerror(self):
        d = Dict()
        with self.assertRaises(KeyError):
            value = d['empty']

    def test_attrerror(self):
        d = Dict()
        with self.assertRaises(AttributeError):
            value = d.empty
```

编写单元测试时，我们需要编写一个测试类，从`unittest.TestCase`继承。

以`test`开头的方法就是测试方法，不以`test`开头的方法不被认为是测试方法，测试的时候不会被执行。

对每一类测试都需要编写一个`test_xxx()`方法。由于`unittest.TestCase`提供了很多内置的条件判断，我们只需要调用这些方法就可以断言输出是否是我们所期望的。最常用的断言就是`assertEqual()`：

```python
self.assertEqual(abs(-1), 1) # 断言函数返回的结果与1相等
```

另一种重要的断言就是期待抛出指定类型的Error，比如通过`d['empty']`访问不存在的key时，断言会抛出`KeyError`：

```python
with self.assertRaises(KeyError):
    value = d['empty']
```

而通过`d.empty`访问不存在的key时，我们期待抛出`AttributeError`：

```python
with self.assertRaises(AttributeError):
    value = d.empty
```

- **运行单元测试**

最简单的运行方式是在`mydict_test.py`的最后加上两行代码：

```python
if __name__ == '__main__':
    unittest.main()
```

这样就可以把`mydict_test.py`当做正常的python脚本运行：

```python
$ python mydict_test.py
```

另一种方法是在命令行通过参数`-m unittest`直接运行单元测试：

```python
$ python -m unittest mydict_test
.....
----------------------------------------------------------------------
Ran 5 tests in 0.000s

OK
```

这是推荐的做法，因为这样可以一次批量运行很多单元测试，并且，有很多工具可以自动来运行这些单元测试。

- **补充**

可以在单元测试中编写两个特殊的`setUp()`和`tearDown()`方法。这两个方法会分别在每调用一个测试方法的前后分别被执行。

`setUp()`和`tearDown()`方法有什么用呢？设想你的测试需要启动一个数据库，这时，就可以在`setUp()`方法中连接数据库，在`tearDown()`方法中关闭数据库，这样，不必在每个测试方法中重复相同的代码：

```python
class TestDict(unittest.TestCase):

    def setUp(self):
        print('setUp...')

    def tearDown(self):
        print('tearDown...')
```

可以再次运行测试看看每个测试方法调用前后是否会打印出`setUp...`和`tearDown...`。



## 四、文档测试

Python内置的“文档测试”（doctest）模块可以直接提取注释中的代码并执行测试。

`doctest`严格按照Python交互式命令行的输入和输出来判断测试结果是否正确。只有测试异常的时候，可以用`...`表示中间一大段烦人的输出。

- **例子**

  ``` python
  # mydict2.py
  class Dict(dict):
      '''
      Simple dict but also support access as x.y style.
  
      >>> d1 = Dict()
      >>> d1['x'] = 100
      >>> d1.x
      100
      >>> d1.y = 200
      >>> d1['y']
      200
      >>> d2 = Dict(a=1, b=2, c='3')
      >>> d2.c
      '3'
      >>> d2['empty']
      Traceback (most recent call last):
          ...
      KeyError: 'empty'
      >>> d2.empty
      Traceback (most recent call last):
          ...
      AttributeError: 'Dict' object has no attribute 'empty'
      '''
      def __init__(self, **kw):
          super(Dict, self).__init__(**kw)
  
      def __getattr__(self, key):
          try:
              return self[key]
          except KeyError:
              raise AttributeError(r"'Dict' object has no attribute '%s'" % key)
  
      def __setattr__(self, key, value):
          self[key] = value
  
  if __name__=='__main__':
      import doctest
      doctest.testmod()
  ```

  

- **运行分析**

若程序运行正确无输出，否从输出错误，下面为删除`__getattr__()`方法后输出：

```python
$ python mydict2.py
**********************************************************************
File "/Users/michael/Github/learn-python3/samples/debug/mydict2.py", line 10, in __main__.Dict
Failed example:
    d1.x
Exception raised:
    Traceback (most recent call last):
      ...
    AttributeError: 'Dict' object has no attribute 'x'
**********************************************************************
File "/Users/michael/Github/learn-python3/samples/debug/mydict2.py", line 16, in __main__.Dict
Failed example:
    d2.c
Exception raised:
    Traceback (most recent call last):
      ...
    AttributeError: 'Dict' object has no attribute 'c'
**********************************************************************
1 items had failures:
   2 of   9 in __main__.Dict
***Test Failed*** 2 failures.
```

最后3行代码为测试输出。当模块正常导入时，doctest不会被执行。只有在命令行直接运行时，才执行doctest。所以，不必担心doctest会在非测试环境下执行。



## 参考

[廖雪峰-错误、调试和测试](https://www.liaoxuefeng.com/wiki/0014316089557264a6b348958f449949df42a6d3a2e542c000/00143191629979802b566644aa84656b50cd484ec4a7838000)